Workbook

Sheet CRM Dashboard
A2: CRM | B2: CRM CAMPAIGN CONTROL CENTER | J2: PERIOD | M2: CHANNEL
J4: All | M4: All
B5: TOTAL CALLS | F5: TOTAL SMS | J5: TOTAL EMAILS | N5: COMPLETION RATE
A6: ▦ | B6: =COUNTIFS('Raw Data'!$C$2:$C$251,"Call",'Raw Data'!$A$2:$A$251,">="&IF($J$4="All",DATE(2026,1,1),DATEVALUE("1 "&$J$4)),'Raw Data'!$A$2:$A$251,"<"&IF($J$4="All",DATE(2026,11,1),EDATE(DATEVALUE("1 "&$J$4),1))) | F6: =COUNTIFS('Raw Data'!$C$2:$C$251,"SMS",'Raw Data'!$A$2:$A$251,">="&IF($J$4="All",DATE(2026,1,1),DATEVALUE("1 "&$J$4)),'Raw Data'!$A$2:$A$251,"<"&IF($J$4="All",DATE(2026,11,1),EDATE(DATEVALUE("1 "&$J$4),1))) | J6: =COUNTIFS('Raw Data'!$C$2:$C$251,"Email",'Raw Data'!$A$2:$A$251,">="&IF($J$4="All",DATE(2026,1,1),DATEVALUE("1 "&$J$4)),'Raw Data'!$A$2:$A$251,"<"&IF($J$4="All",DATE(2026,11,1),EDATE(DATEVALUE("1 "&$J$4),1))) | N6: =IFERROR(COUNTIFS('Raw Data'!$F$2:$F$251,"Completed")/COUNTA('Raw Data'!$A$2:$A$251),0)
B9: CAMPAIGN PERFORMANCE | J9: CHANNEL MIX
A10: ◉
A14: ▤
A18: ◷
A22: ●
A26: ⚙ | B26: STATUS BREAKDOWN | J26: RECENT ACTIVITY
B28: Status | C28: Count | J28: Date | K28: Channel | L28: Status
B29: Completed | C29: =COUNTIF('Raw Data'!$F$2:$F$251,B29) | D29: On track | J29: ='Raw Data'!A251 | K29: ='Raw Data'!C251 | L29: ='Raw Data'!F251
B30: Pending | C30: =COUNTIF('Raw Data'!$F$2:$F$251,B30) | D30: Awaiting response | J30: ='Raw Data'!A250 | K30: ='Raw Data'!C250 | L30: ='Raw Data'!F250
B31: Failed | C31: =COUNTIF('Raw Data'!$F$2:$F$251,B31) | D31: Needs attention | J31: ='Raw Data'!A249 | K31: ='Raw Data'!C249 | L31: ='Raw Data'!F249
J32: ='Raw Data'!A248 | K32: ='Raw Data'!C248 | L32: ='Raw Data'!F248
J33: ='Raw Data'!A247 | K33: ='Raw Data'!C247 | L33: ='Raw Data'!F247
B36: SAMPLE CRM DATA • Use the dropdowns above to explore the dashboard. Replace the Raw Data sheet with your own records to customize it.

Sheet Raw Data
A1: Date | B1: Campaign | C1: Channel | D1: Caller ID | E1: Destination | F1: Status | G1: Response Time (min) | H1: Agent
A2: 46290.619 | B2: Win-back Campaign | C2: SMS | D2: client@example.com | E2: team@example.com | F2: Completed | G2: 12 | H2: Taylor Morgan
A3: 46079.344 | B3: Renewal Reminder | C3: SMS | D3: +1 555 2310 | E3: client@example.com | F3: Pending | G3: 42 | H3: Jordan Lee
A4: 46305.339 | B4: Win-back Campaign | C4: Email | D4: alex@example.com | E4: team@example.com | F4: Pending | G4: 29 | H4: Jordan Lee
A5: 46192.672 | B5: Customer Survey | C5: Email | D5: +1 555 0531 | E5: team@example.com | F5: Completed | G5: 20 | H5: Casey Patel
A6: 46095.785 | B6: Welcome Series | C6: SMS | D6: +1 555 7642 | E6: +1 555 3492 | F6: Completed | G6: 22 | H6: Riley Chen
A7: 46049.544 | B7: Customer Survey | C7: Email | D7: +1 555 1359 | E7: +1 555 2409 | F7: Completed | G7: 1 | H7: Riley Chen
A8: 46132.481 | B8: Newsletter | C8: Email | D8: +1 555 1359 | E8: team@example.com | F8: Completed | G8: 5 | H8: Riley Chen
A9: 46295.706 | B9: Newsletter | C9: Call | D9: +1 555 1359 | E9: +1 555 3492 | F9: Completed | G9: 23 | H9: Alexandra Rose
A10: 46162.542 | B10: Welcome Series | C10: Call | D10: +1 555 7642 | E10: +1 555 3492 | F10: Failed | H10: Casey Patel
A11: 46050.472 | B11: Customer Survey | C11: Call | D11: +1 555 0531 | E11: team@example.com | F11: Pending | G11: 101 | H11: Riley Chen
A12: 46291.756 | B12: Customer Survey | C12: SMS | D12: +1 555 1359 | E12: +1 555 5630 | F12: Pending | G12: 85 | H12: Taylor Morgan
A13: 46100.755 | B13: Newsletter | C13: Email | D13: +1 555 2310 | E13: +1 555 3492 | F13: Completed | G13: 35 | H13: Alexandra Rose
A14: 46105.587 | B14: Win-back Campaign | C14: Email | D14: +1 555 7642 | E14: client@example.com | F14: Completed | G14: 17 | H14: Alexandra Rose
A15: 46300.399 | B15: Newsletter | C15: Email | D15: alex@example.com | E15: +1 555 5630 | F15: Completed | G15: 35 | H15: Taylor Morgan
A16: 46048.651 | B16: Customer Survey | C16: SMS | D16: alex@example.com | E16: client@example.com | F16: Completed | G16: 36 | H16: Alexandra Rose
A17: 46258.468 | B17: Renewal Reminder | C17: SMS | D17: +1 555 0531 | E17: team@example.com | F17: Pending | G17: 56 | H17: Riley Chen
A18: 46288.585 | B18: Product Launch | C18: Email | D18: alex@example.com | E18: +1 555 5630 | F18: Completed | G18: 38 | H18: Riley Chen
A19: 46183.549 | B19: Customer Survey | C19: Email | D19: +1 555 2310 | E19: client@example.com | F19: Pending | G19: 48 | H19: Riley Chen
A20: 46070.671 | B20: Win-back Campaign | C20: SMS | D20: alex@example.com | E20: +1 555 5630 | F20: Completed | G20: 37 | H20: Casey Patel
A21: 46260.662 | B21: Customer Survey | C21: SMS | D21: +1 555 0531 | E21: +1 555 3492 | F21: Completed | G21: 31 | H21: Taylor Morgan
A22: 46117.369 | B22: Product Launch | C22: Email | D22: +1 555 0531 | E22: +1 555 3492 | F22: Completed | G22: 22 | H22: Alexandra Rose
... A45: 46157.71 | B45: Newsletter | C45: Email | D45: alex@example.com | E45: team@example.com | F45: Completed | G45: 35 | H45: Alexandra Rose
A46: 46051.512 | B46: Product Launch | C46: SMS | D46: alex@example.com | E46: +1 555 2409 | F46: Failed | H46: Alexandra Rose
A47: 46213.562 | B47: Newsletter | C47: SMS | D47: +1 555 1359 | E47: +1 555 2409 | F47: Pending | G47: 73 | H47: Riley Chen
A48: 46081.565 | B48: Renewal Reminder | C48: Email | D48: alex@example.com | E48: +1 555 2409 | F48: Pending | G48: 24 | H48: Alexandra Rose
A49: 46223.405 | B49: Renewal Reminder | C49: Email | D49: +1 555 7642 | E49: +1 555 2409 | F49: Completed | G49: 13 | H49: Taylor Morgan
A50: 46032.713 | B50: Newsletter | C50: Email | D50: client@example.com | E50: +1 555 3492 | F50: Completed | G50: 15 | H50: Taylor Morgan
A51: 46192.667 | B51: Customer Survey | C51: SMS | D51: +1 555 0531 | E51: +1 555 3492 | F51: Completed | G51: 41 | H51: Riley Chen
A52: 46188.666 | B52: Renewal Reminder | C52: Email | D52: client@example.com | E52: client@example.com | F52: Pending | G52: 21 | H52: Taylor Morgan
A53: 46085.745 | B53: Win-back Campaign | C53: Email | D53: +1 555 2310 | E53: +1 555 2409 | F53: Pending | G53: 19 | H53: Jordan Lee
A54: 46125.533 | B54: Welcome Series | C54: SMS | D54: +1 555 7642 | E54: team@example.com | F54: Completed | G54: 25 | H54: Casey Patel
A55: 46234.761 | B55: Renewal Reminder | C55: SMS | D55: +1 555 1359 | E55: +1 555 5630 | F55: Completed | G55: 26 | H55: Taylor Morgan
A56: 46141.764 | B56: Renewal Reminder | C56: SMS | D56: +1 555 0531 | E56: +1 555 5630 | F56: Pending | G56: 37 | H56: Riley Chen
A57: 46262.478 | B57: Welcome Series | C57: SMS | D57: +1 555 1359 | E57: +1 555 2409 | F57: Pending | G57: 89 | H57: Jordan Lee
A58: 46025.502 | B58: Customer Survey | C58: Email | D58: +1 555 7642 | E58: +1 555 2409 | F58: Pending | G58: 56 | H58: Riley Chen
... A62: 46218.613 | B62: Product Launch | C62: Email | D62: +1 555 1359 | E62: +1 555 2409 | F62: Completed | G62: 13 | H62: Riley Chen
A63: 46262.548 | B63: Win-back Campaign | C63: SMS | D63: +1 555 2310 | E63: +1 555 3492 | F63: Failed | H63: Casey Patel
A64: 46263.383 | B64: Welcome Series | C64: Call | D64: +1 555 2310 | E64: team@example.com | F64: Completed | G64: 20 | H64: Riley Chen
A65: 46154.561 | B65: Newsletter | C65: Call | D65: client@example.com | E65: +1 555 5630 | F65: Completed | G65: 29 | H65: Riley Chen
...

Sheet Analysis
A1: Month | B1: Calls | C1: SMS | D1: Emails | E1: Completed | F1: Pending | G1: Failed | I1: Channel | J1: Interactions
A2: 46023 | B2: =COUNTIFS('Raw Data'!$A$2:$A$251,">="&A2,'Raw Data'!$A$2:$A$251,"<"&EDATE(A2,1),'Raw Data'!$C$2:$C$251,B$14) | C2: =COUNTIFS('Raw Data'!$A$2:$A$251,">="&A2,'Raw Data'!$A$2:$A$251,"<"&EDATE(A2,1),'Raw Data'!$C$2:$C$251,C$14) | D2: =COUNTIFS('Raw Data'!$A$2:$A$251,">="&A2,'Raw Data'!$A$2:$A$251,"<"&EDATE(A2,1),'Raw Data'!$C$2:$C$251,D$14) | E2: =COUNTIFS('Raw Data'!$A$2:$A$251,">="&A2,'Raw Data'!$A$2:$A$251,"<"&EDATE(A2,1),'Raw Data'!$F$2:$F$251,"Completed") | F2: =COUNTIFS('Raw Data'!$A$2:$A$251,">="&A2,'Raw Data'!$A$2:$A$251,"<"&EDATE(A2,1),'Raw Data'!$F$2:$F$251,"Pending") | G2: =COUNTIFS('Raw Data'!$A$2:$A$251,">="&A2,'Raw Data'!$A$2:$A$251,"<"&EDATE(A2,1),'Raw Data'!$F$2:$F$251,"Failed") | I2: Call | J2: =COUNTIF('Raw Data'!$C$2:$C$251,I2)
A3: 46054 | B3: =COUNTIFS('Raw Data'!$A$2:$A$251,">="&A3,'Raw Data'!$A$2:$A$251,"<"&EDATE(A3,1),'Raw Data'!$C$2:$C$251,B$14) | C3: =COUNTIFS('Raw Data'!$A$2:$A$251,">="&A3,'Raw Data'!$A$2:$A$251,"<"&EDATE(A3,1),'Raw Data'!$C$2:$C$251,C$14) | D3: =COUNTIFS('Raw Data'!$A$2:$A$251,">="&A3,'Raw Data'!$A$2:$A$251,"<"&EDATE(A3,1),'Raw Data'!$C$2:$C$251,D$14) | E3: =COUNTIFS('Raw Data'!$A$2:$A$251,">="&A3,'Raw Data'!$A$2:$A$251,"<"&EDATE(A3,1),'Raw Data'!$F$2:$F$251,"Completed") | F3: =COUNTIFS('Raw Data'!$A$2:$A$251,">="&A3,'Raw Data'!$A$2:$A$251,"<"&EDATE(A3,1),'Raw Data'!$F$2:$F$251,"Pending") | G3: =COUNTIFS('Raw Data'!$A$2:$A$251,">="&A3,'Raw Data'!$A$2:$A$251,"<"&EDATE(A3,1),'Raw Data'!$F$2:$F$251,"Failed") | I3: SMS | J3: =COUNTIF('Raw Data'!$C$2:$C$251,I3)
A4: 46082 | B4: =COUNTIFS('Raw Data'!$A$2:$A$251,">="&A4,'Raw Data'!$A$2:$A$251,"<"&EDATE(A4,1),'Raw Data'!$C$2:$C$251,B$14) | C4: =COUNTIFS('Raw Data'!$A$2:$A$251,">="&A4,'Raw Data'!$A$2:$A$251,"<"&EDATE(A4,1),'Raw Data'!$C$2:$C$251,C$14) | D4: =COUNTIFS('Raw Data'!$A$2:$A$251,">="&A4,'Raw Data'!$A$2:$A$251,"<"&EDATE(A4,1),'Raw Data'!$C$2:$C$251,D$14) | E4: =COUNTIFS('Raw Data'!$A$2:$A$251,">="&A4,'Raw Data'!$A$2:$A$251,"<"&EDATE(A4,1),'Raw Data'!$F$2:$F$251,"Completed") | F4: =COUNTIFS('Raw Data'!$A$2:$A$251,">="&A4,'Raw Data'!$A$2:$A$251,"<"&EDATE(A4,1),'Raw Data'!$F$2:$F$251,"Pending") | G4: =COUNTIFS('Raw Data'!$A$2:$A$251,">="&A4,'Raw Data'!$A$2:$A$251,"<"&EDATE(A4,1),'Raw Data'!$F$2:$F$251,"Failed") | I4: Email | J4: =COUNTIF('Raw Data'!$C$2:$C$251,I4)
A5: 46113 | B5: =COUNTIFS('Raw Data'!$A$2:$A$251,">="&A5,'Raw Data'!$A$2:$A$251,"<"&EDATE(A5,1),'Raw Data'!$C$2:$C$251,B$14) | C5: =COUNTIFS('Raw Data'!$A$2:$A$251,">="&A5,'Raw Data'!$A$2:$A$251,"<"&EDATE(A5,1),'Raw Data'!$C$2:$C$251,C$14) | D5: =COUNTIFS('Raw Data'!$A$2:$A$251,">="&A5,'Raw Data'!$A$2:$A$251,"<"&EDATE(A5,1),'Raw Data'!$C$2:$C$251,D$14) | E5: =COUNTIFS('Raw Data'!$A$2:$A$251,">="&A5,'Raw Data'!$A$2:$A$251,"<"&EDATE(A5,1),'Raw Data'!$F$2:$F$251,"Completed") | F5: =COUNTIFS('Raw Data'!$A$2:$A$251,">="&A5,'Raw Data'!$A$2:$A$251,"<"&EDATE(A5,1),'Raw Data'!$F$2:$F$251,"Pending") | G5: =COUNTIFS('Raw Data'!$A$2:$A$251,">="&A5,'Raw Data'!$A$2:$A$251,"<"&EDATE(A5,1),'Raw Data'!$F$2:$F$251,"Failed")
A6: 46143 | B6: =COUNTIFS('Raw Data'!$A$2:$A$251,">="&A6,'Raw Data'!$A$2:$A$251,"<"&EDATE(A6,1),'Raw Data'!$C$2:$C$251,B$14) | C6: =COUNTIFS('Raw Data'!$A$2:$A$251,">="&A6,'Raw Data'!$A$2:$A$251,"<"&EDATE(A6,1),'Raw Data'!$C$2:$C$251,C$14) | D6: =COUNTIFS('Raw Data'!$A$2:$A$251,">="&A6,'Raw Data'!$A$2:$A$251,"<"&EDATE(A6,1),'Raw Data'!$C$2:$C$251,D$14) | E6: =COUNTIFS('Raw Data'!$A$2:$A$251,">="&A6,'Raw Data'!$A$2:$A$251,"<"&EDATE(A6,1),'Raw Data'!$F$2:$F$251,"Completed") | F6: =COUNTIFS('Raw Data'!$A$2:$A$251,">="&A6,'Raw Data'!$A$2:$A$251,"<"&EDATE(A6,1),'Raw Data'!$F$2:$F$251,"Pending") | G6: =COUNTIFS('Raw Data'!$A$2:$A$251,">="&A6,'Raw Data'!$A$2:$A$251,"<"&EDATE(A6,1),'Raw Data'!$F$2:$F$251,"Failed")
A7: 46174 | B7: =COUNTIFS('Raw Data'!$A$2:$A$251,">="&A7,'Raw Data'!$A$2:$A$251,"<"&EDATE(A7,1),'Raw Data'!$C$2:$C$251,B$14) | C7: =COUNTIFS('Raw Data'!$A$2:$A$251,">="&A7,'Raw Data'!$A$2:$A$251,"<"&EDATE(A7,1),'Raw Data'!$C$2:$C$251,C$14) | D7: =COUNTIFS('Raw Data'!$A$2:$A$251,">="&A7,'Raw Data'!$A$2:$A$251,"<"&EDATE(A7,1),'Raw Data'!$C$2:$C$251,D$14) | E7: =COUNTIFS('Raw Data'!$A$2:$A$251,">="&A7,'Raw Data'!$A$2:$A$251,"<"&EDATE(A7,1),'Raw Data'!$F$2:$F$251,"Completed") | F7: =COUNTIFS('Raw Data'!$A$2:$A$251,">="&A7,'Raw Data'!$A$2:$A$251,"<"&EDATE(A7,1),'Raw Data'!$F$2:$F$251,"Pending") | G7: =COUNTIFS('Raw Data'!$A$2:$A$251,">="&A7,'Raw Data'!$A$2:$A$251,"<"&EDATE(A7,1),'Raw Data'!$F$2:$F$251,"Failed")
A8: 46204 | B8: =COUNTIFS('Raw Data'!$A$2:$A$251,">="&A8,'Raw Data'!$A$2:$A$251,"<"&EDATE(A8,1),'Raw Data'!$C$2:$C$251,B$14) | C8: =COUNTIFS('Raw Data'!$A$2:$A$251,">="&A8,'Raw Data'!$A$2:$A$251,"<"&EDATE(A8,1),'Raw Data'!$C$2:$C$251,C$14) | D8: =COUNTIFS('Raw Data'!$A$2:$A$251,">="&A8,'Raw Data'!$A$2:$A$251,"<"&EDATE(A8,1),'Raw Data'!$C$2:$C$251,D$14) | E8: =COUNTIFS('Raw Data'!$A$2:$A$251,">="&A8,'Raw Data'!$A$2:$A$251,"<"&EDATE(A8,1),'Raw Data'!$F$2:$F$251,"Completed") | F8: =COUNTIFS('Raw Data'!$A$2:$A$251,">="&A8,'Raw Data'!$A$2:$A$251,"<"&EDATE(A8,1),'Raw Data'!$F$2:$F$251,"Pending") | G8: =COUNTIFS('Raw Data'!$A$2:$A$251,">="&A8,'Raw Data'!$A$2:$A$251,"<"&EDATE(A8,1),'Raw Data'!$F$2:$F$251,"Failed")
A9: 46235 | B9: =COUNTIFS('Raw Data'!$A$2:$A$251,">="&A9,'Raw Data'!$A$2:$A$251,"<"&EDATE(A9,1),'Raw Data'!$C$2:$C$251,B$14) | C9: =COUNTIFS('Raw Data'!$A$2:$A$251,">="&A9,'Raw Data'!$A$2:$A$251,"<"&EDATE(A9,1),'Raw Data'!$C$2:$C$251,C$14) | D9: =COUNTIFS('Raw Data'!$A$2:$A$251,">="&A9,'Raw Data'!$A$2:$A$251,"<"&EDATE(A9,1),'Raw Data'!$C$2:$C$251,D$14) | E9: =COUNTIFS('Raw Data'!$A$2:$A$251,">="&A9,'Raw Data'!$A$2:$A$251,"<"&EDATE(A9,1),'Raw Data'!$F$2:$F$251,"Completed") | F9: =COUNTIFS('Raw Data'!$A$2:$A$251,">="&A9,'Raw Data'!$A$2:$A$251,"<"&EDATE(A9,1),'Raw Data'!$F$2:$F$251,"Pending") | G9: =COUNTIFS('Raw Data'!$A$2:$A$251,">="&A9,'Raw Data'!$A$2:$A$251,"<"&EDATE(A9,1),'Raw Data'!$F$2:$F$251,"Failed")
A10: 46266 | B10: =COUNTIFS('Raw Data'!$A$2:$A$251,">="&A10,'Raw Data'!$A$2:$A$251,"<"&EDATE(A10,1),'Raw Data'!$C$2:$C$251,B$14) | C10: =COUNTIFS('Raw Data'!$A$2:$A$251,">="&A10,'Raw Data'!$A$2:$A$251,"<"&EDATE(A10,1),'Raw Data'!$C$2:$C$251,C$14) | D10: =COUNTIFS('Raw Data'!$A$2:$A$251,">="&A10,'Raw Data'!$A$2:$A$251,"<"&EDATE(A10,1),'Raw Data'!$C$2:$C$251,D$14) | E10: =COUNTIFS('Raw Data'!$A$2:$A$251,">="&A10,'Raw Data'!$A$2:$A$251,"<"&EDATE(A10,1),'Raw Data'!$F$2:$F$251,"Completed") | F10: =COUNTIFS('Raw Data'!$A$2:$A$251,">="&A10,'Raw Data'!$A$2:$A$251,"<"&EDATE(A10,1),'Raw Data'!$F$2:$F$251,"Pending") | G10: =COUNTIFS('Raw Data'!$A$2:$A$251,">="&A10,'Raw Data'!$A$2:$A$251,"<"&EDATE(A10,1),'Raw Data'!$F$2:$F$251,"Failed")
A11: 46296 | B11: =COUNTIFS('Raw Data'!$A$2:$A$251,">="&A11,'Raw Data'!$A$2:$A$251,"<"&EDATE(A11,1),'Raw Data'!$C$2:$C$251,B$14) | C11: =COUNTIFS('Raw Data'!$A$2:$A$251,">="&A11,'Raw Data'!$A$2:$A$251,"<"&EDATE(A11,1),'Raw Data'!$C$2:$C$251,C$14) | D11: =COUNTIFS('Raw Data'!$A$2:$A$251,">="&A11,'Raw Data'!$A$2:$A$251,"<"&EDATE(A11,1),'Raw Data'!$C$2:$C$251,D$14) | E11: =COUNTIFS('Raw Data'!$A$2:$A$251,">="&A11,'Raw Data'!$A$2:$A$251,"<"&EDATE(A11,1),'Raw Data'!$F$2:$F$251,"Completed") | F11: =COUNTIFS('Raw Data'!$A$2:$A$251,">="&A11,'Raw Data'!$A$2:$A$251,"<"&EDATE(A11,1),'Raw Data'!$F$2:$F$251,"Pending") | G11: =COUNTIFS('Raw Data'!$A$2:$A$251,">="&A11,'Raw Data'!$A$2:$A$251,"<"&EDATE(A11,1),'Raw Data'!$F$2:$F$251,"Failed")
A14: Channel | B14: Call | C14: SMS | D14: Email

Sheet Read Me
A1: CRM Dashboard — Quick Start
A3: 1. Explore | B3: Use the Period and Channel dropdowns on the Dashboard. KPI cards and the monthly chart are linked to the workbook data.
A4: 2. Sample data | B4: The Raw Data sheet contains 250 fictional CRM interactions for demonstration.
A5: 3. Replace data | B5: Keep the same column headings and replace the sample rows with your CRM records. Update formulas if you add more than 250 rows.
A6: 4. Excel compatibility | B6: Open in desktop Microsoft Excel for best chart and formula support. Some formula results may appear after Excel recalculates the workbook.
A7: 5. Extend | B7: You can add PivotTables and native slicers in Excel if you want pivot-driven filtering beyond the dropdowns included here.
